
Running model pipeline for data fold 1...
Label column '5y' found in metadata. Available columns: ['pid', 'study_yr', 'path', 'sct_slice_num_og', 'stage', '1y', '2y', '5y', '10y', 'fup_days', 'sct_nod_err', 'lung_side', 'de_stag', 'de_stag_7thed', 'sct_slice_new']
Label weights: tensor([1.], device='cuda:0', dtype=torch.float64)
C:\Users\HP\.conda\envs\pipeline\Lib\site-packages\pytorch_lightning\trainer\connectors\data_connector.py:442: PossibleUserWarning: The dataloader, val_dataloader, does not have many workers which may be a bottleneck. Consider increasing the value of the `num_workers` argument` (try 12 which is the number of cpus on this machine) in the `DataLoader` init to improve performance.
  rank_zero_warn(
✅ Upload successful: slice_215002_2.png
✅ Upload successful: slice_121004_0.png
[ERROR] Error in __getitem__ at index 2: cannot access local variable 'response' where it is not associated with a value
File path: C:\Users\HP\OneDrive - Universidade do Porto\Documentos\UNIVERSIDADE\Tese\PhantomDataset/133279/2.000000-2OPAGELS16D4002.5120869.0nullnull-51493
Label: 0
Error executing job with overrides: []
urllib3.exceptions.SSLError: EOF occurred in violation of protocol (_ssl.c:2427)

The above exception was the direct cause of the following exception:

Traceback (most recent call last):
  File "C:\Users\HP\.conda\envs\pipeline\Lib\site-packages\requests\adapters.py", line 667, in send
    resp = conn.urlopen(
           ^^^^^^^^^^^^^
  File "C:\Users\HP\.conda\envs\pipeline\Lib\site-packages\urllib3\connectionpool.py", line 841, in urlopen
    retries = retries.increment(
              ^^^^^^^^^^^^^^^^^^
  File "C:\Users\HP\.conda\envs\pipeline\Lib\site-packages\urllib3\util\retry.py", line 519, in increment
    raise MaxRetryError(_pool, url, reason) from reason  # type: ignore[arg-type]
    ^^^^^^^^^^^^^^^^^^^^^^^^^^^^^^^^^^^^^^^^^^^^^^^^^^^
urllib3.exceptions.MaxRetryError: HTTPSConnectionPool(host='api.imgur.com', port=443): Max retries exceeded with url: /3/upload (Caused by SSLError(SSLEOFError(8, 'EOF occurred in violation of protocol (_ssl.c:2427)')))

During handling of the above exception, another exception occurred:

Traceback (most recent call last):
  File "C:\Users\HP\OneDrive - Universidade do Porto\Documentos\UNIVERSIDADE\Tese\pytorch_lightning_dl_pipeline_template\src\modules\data\dataloader\visualizationuploader.py", line 50, in upload_image
    response = requests.post(
               ^^^^^^^^^^^^^^
  File "C:\Users\HP\.conda\envs\pipeline\Lib\site-packages\requests\api.py", line 115, in post
    return request("post", url, data=data, json=json, **kwargs)
           ^^^^^^^^^^^^^^^^^^^^^^^^^^^^^^^^^^^^^^^^^^^^^^^^^^^^
  File "C:\Users\HP\.conda\envs\pipeline\Lib\site-packages\requests\api.py", line 59, in request
    return session.request(method=method, url=url, **kwargs)
           ^^^^^^^^^^^^^^^^^^^^^^^^^^^^^^^^^^^^^^^^^^^^^^^^^
  File "C:\Users\HP\.conda\envs\pipeline\Lib\site-packages\requests\sessions.py", line 589, in request
    resp = self.send(prep, **send_kwargs)
           ^^^^^^^^^^^^^^^^^^^^^^^^^^^^^^
  File "C:\Users\HP\.conda\envs\pipeline\Lib\site-packages\requests\sessions.py", line 703, in send
    r = adapter.send(request, **kwargs)
        ^^^^^^^^^^^^^^^^^^^^^^^^^^^^^^^
  File "C:\Users\HP\.conda\envs\pipeline\Lib\site-packages\requests\adapters.py", line 698, in send
    raise SSLError(e, request=request)
requests.exceptions.SSLError: HTTPSConnectionPool(host='api.imgur.com', port=443): Max retries exceeded with url: /3/upload (Caused by SSLError(SSLEOFError(8, 'EOF occurred in violation of protocol (_ssl.c:2427)')))

During handling of the above exception, another exception occurred:

Traceback (most recent call last):
  File "C:\Users\HP\OneDrive - Universidade do Porto\Documentos\UNIVERSIDADE\Tese\pytorch_lightning_dl_pipeline_template\src\scripts\run_experiment_pipeline.py", line 59, in run_hyperparameter_grid_based_execution_pipeline
    run_experiment_pipeline(config)
  File "C:\Users\HP\OneDrive - Universidade do Porto\Documentos\UNIVERSIDADE\Tese\pytorch_lightning_dl_pipeline_template\src\scripts\run_experiment_pipeline.py", line 167, in run_experiment_pipeline
    model_pipeline.train_model()
  File "C:\Users\HP\OneDrive - Universidade do Porto\Documentos\UNIVERSIDADE\Tese\pytorch_lightning_dl_pipeline_template\src\modules\model\model_pipeline.py", line 68, in train_model
    self.pytorch_lightning_trainer.fit(
  File "C:\Users\HP\.conda\envs\pipeline\Lib\site-packages\pytorch_lightning\trainer\trainer.py", line 532, in fit
    call._call_and_handle_interrupt(
  File "C:\Users\HP\.conda\envs\pipeline\Lib\site-packages\pytorch_lightning\trainer\call.py", line 43, in _call_and_handle_interrupt
    return trainer_fn(*args, **kwargs)
           ^^^^^^^^^^^^^^^^^^^^^^^^^^^
  File "C:\Users\HP\.conda\envs\pipeline\Lib\site-packages\pytorch_lightning\trainer\trainer.py", line 571, in _fit_impl
    self._run(model, ckpt_path=ckpt_path)
  File "C:\Users\HP\.conda\envs\pipeline\Lib\site-packages\pytorch_lightning\trainer\trainer.py", line 980, in _run
    results = self._run_stage()
              ^^^^^^^^^^^^^^^^^
  File "C:\Users\HP\.conda\envs\pipeline\Lib\site-packages\pytorch_lightning\trainer\trainer.py", line 1021, in _run_stage
    self._run_sanity_check()
  File "C:\Users\HP\.conda\envs\pipeline\Lib\site-packages\pytorch_lightning\trainer\trainer.py", line 1050, in _run_sanity_check
    val_loop.run()
  File "C:\Users\HP\.conda\envs\pipeline\Lib\site-packages\pytorch_lightning\loops\utilities.py", line 181, in _decorator
    return loop_run(self, *args, **kwargs)
           ^^^^^^^^^^^^^^^^^^^^^^^^^^^^^^^
  File "C:\Users\HP\.conda\envs\pipeline\Lib\site-packages\pytorch_lightning\loops\evaluation_loop.py", line 108, in run
    batch, batch_idx, dataloader_idx = next(data_fetcher)
                                       ^^^^^^^^^^^^^^^^^^
  File "C:\Users\HP\.conda\envs\pipeline\Lib\site-packages\pytorch_lightning\loops\fetchers.py", line 126, in __next__
    batch = super().__next__()
            ^^^^^^^^^^^^^^^^^^
  File "C:\Users\HP\.conda\envs\pipeline\Lib\site-packages\pytorch_lightning\loops\fetchers.py", line 58, in __next__
    batch = next(self.iterator)
            ^^^^^^^^^^^^^^^^^^^
  File "C:\Users\HP\.conda\envs\pipeline\Lib\site-packages\pytorch_lightning\utilities\combined_loader.py", line 285, in __next__
    out = next(self._iterator)
          ^^^^^^^^^^^^^^^^^^^^
  File "C:\Users\HP\.conda\envs\pipeline\Lib\site-packages\pytorch_lightning\utilities\combined_loader.py", line 123, in __next__
    out = next(self.iterators[0])
          ^^^^^^^^^^^^^^^^^^^^^^^
  File "C:\Users\HP\.conda\envs\pipeline\Lib\site-packages\torch\utils\data\dataloader.py", line 733, in __next__
    data = self._next_data()
           ^^^^^^^^^^^^^^^^^
  File "C:\Users\HP\.conda\envs\pipeline\Lib\site-packages\torch\utils\data\dataloader.py", line 789, in _next_data
    data = self._dataset_fetcher.fetch(index)  # may raise StopIteration
           ^^^^^^^^^^^^^^^^^^^^^^^^^^^^^^^^^^
  File "C:\Users\HP\.conda\envs\pipeline\Lib\site-packages\torch\utils\data\_utils\fetch.py", line 52, in fetch
    data = [self.dataset[idx] for idx in possibly_batched_index]
           ^^^^^^^^^^^^^^^^^^^^^^^^^^^^^^^^^^^^^^^^^^^^^^^^^^^^^
  File "C:\Users\HP\.conda\envs\pipeline\Lib\site-packages\torch\utils\data\_utils\fetch.py", line 52, in <listcomp>
    data = [self.dataset[idx] for idx in possibly_batched_index]
            ~~~~~~~~~~~~^^^^^
  File "C:\Users\HP\OneDrive - Universidade do Porto\Documentos\UNIVERSIDADE\Tese\pytorch_lightning_dl_pipeline_template\src\modules\data\dataloader\preprocessed_dataloaders\nlstlocal_preprocessed_dataloader.py", line 299, in __getitem__
    raise e
  File "C:\Users\HP\OneDrive - Universidade do Porto\Documentos\UNIVERSIDADE\Tese\pytorch_lightning_dl_pipeline_template\src\modules\data\dataloader\preprocessed_dataloaders\nlstlocal_preprocessed_dataloader.py", line 289, in __getitem__
    data = self._get_data(data_index)
           ^^^^^^^^^^^^^^^^^^^^^^^^^^
  File "C:\Users\HP\OneDrive - Universidade do Porto\Documentos\UNIVERSIDADE\Tese\pytorch_lightning_dl_pipeline_template\src\modules\data\dataloader\preprocessed_dataloaders\nlstlocal_preprocessed_dataloader.py", line 347, in _get_data
    self.visualization_uploader.upload_image(
  File "C:\Users\HP\OneDrive - Universidade do Porto\Documentos\UNIVERSIDADE\Tese\pytorch_lightning_dl_pipeline_template\src\modules\data\dataloader\visualizationuploader.py", line 59, in upload_image
    print(f"❌ Upload failed ({response.status_code}) for {file_name}")
          ^^^^^^^^^^^^^^^^^^^^^^^^^^^^^^^^^^^^^^^^^^^^^^^^^^^^^^^^^^^^
UnboundLocalError: cannot access local variable 'response' where it is not associated with a value

Set the environment variable HYDRA_FULL_ERROR=1 for a complete stack trace.
