Initialization time: 2025-05-14 22:01:47

**************************************************  Experiment 44 | Version 1 **************************************************
Label column '5y' found in metadata. Available columns: ['pid', 'study_yr', 'path', 'sct_slice_num_og', 'stage', '1y', '2y', '5y', '10y', 'fup_days', 'sct_nod_err']

Running model pipeline for data fold 1...
Label column '5y' found in metadata. Available columns: ['pid', 'study_yr', 'path', 'sct_slice_num_og', 'stage', '1y', '2y', '5y', '10y', 'fup_days', 'sct_nod_err']
Error executing job with overrides: []
Traceback (most recent call last):
  File "/nas-ctm01/homes/mipaiva/pipeline_template_pl/slurm_files/shell_script_files/../../src/scripts/run_experiment_pipeline.py", line 53, in run_hyperparameter_grid_based_execution_pipeline
    run_experiment_pipeline(config)
  File "/nas-ctm01/homes/mipaiva/pipeline_template_pl/slurm_files/shell_script_files/../../src/scripts/run_experiment_pipeline.py", line 139, in run_experiment_pipeline
    model_pipeline.train_model()
  File "/nas-ctm01/homes/mipaiva/pipeline_template_pl/src/modules/model/model_pipeline.py", line 67, in train_model
    self.pytorch_lightning_trainer.fit(
  File "/nas-ctm01/homes/mipaiva/.conda/envs/pipeline/lib/python3.11/site-packages/pytorch_lightning/trainer/trainer.py", line 532, in fit
    call._call_and_handle_interrupt(
  File "/nas-ctm01/homes/mipaiva/.conda/envs/pipeline/lib/python3.11/site-packages/pytorch_lightning/trainer/call.py", line 43, in _call_and_handle_interrupt
    return trainer_fn(*args, **kwargs)
           ^^^^^^^^^^^^^^^^^^^^^^^^^^^
  File "/nas-ctm01/homes/mipaiva/.conda/envs/pipeline/lib/python3.11/site-packages/pytorch_lightning/trainer/trainer.py", line 571, in _fit_impl
    self._run(model, ckpt_path=ckpt_path)
  File "/nas-ctm01/homes/mipaiva/.conda/envs/pipeline/lib/python3.11/site-packages/pytorch_lightning/trainer/trainer.py", line 980, in _run
    results = self._run_stage()
              ^^^^^^^^^^^^^^^^^
  File "/nas-ctm01/homes/mipaiva/.conda/envs/pipeline/lib/python3.11/site-packages/pytorch_lightning/trainer/trainer.py", line 1023, in _run_stage
    self.fit_loop.run()
  File "/nas-ctm01/homes/mipaiva/.conda/envs/pipeline/lib/python3.11/site-packages/pytorch_lightning/loops/fit_loop.py", line 202, in run
    self.advance()
  File "/nas-ctm01/homes/mipaiva/.conda/envs/pipeline/lib/python3.11/site-packages/pytorch_lightning/loops/fit_loop.py", line 355, in advance
    self.epoch_loop.run(self._data_fetcher)
  File "/nas-ctm01/homes/mipaiva/.conda/envs/pipeline/lib/python3.11/site-packages/pytorch_lightning/loops/training_epoch_loop.py", line 133, in run
    self.advance(data_fetcher)
  File "/nas-ctm01/homes/mipaiva/.conda/envs/pipeline/lib/python3.11/site-packages/pytorch_lightning/loops/training_epoch_loop.py", line 190, in advance
    batch = next(data_fetcher)
            ^^^^^^^^^^^^^^^^^^
  File "/nas-ctm01/homes/mipaiva/.conda/envs/pipeline/lib/python3.11/site-packages/pytorch_lightning/loops/fetchers.py", line 126, in __next__
    batch = super().__next__()
            ^^^^^^^^^^^^^^^^^^
  File "/nas-ctm01/homes/mipaiva/.conda/envs/pipeline/lib/python3.11/site-packages/pytorch_lightning/loops/fetchers.py", line 58, in __next__
    batch = next(self.iterator)
            ^^^^^^^^^^^^^^^^^^^
  File "/nas-ctm01/homes/mipaiva/.conda/envs/pipeline/lib/python3.11/site-packages/pytorch_lightning/utilities/combined_loader.py", line 285, in __next__
    out = next(self._iterator)
          ^^^^^^^^^^^^^^^^^^^^
  File "/nas-ctm01/homes/mipaiva/.conda/envs/pipeline/lib/python3.11/site-packages/pytorch_lightning/utilities/combined_loader.py", line 65, in __next__
    out[i] = next(self.iterators[i])
             ^^^^^^^^^^^^^^^^^^^^^^^
  File "/nas-ctm01/homes/mipaiva/.conda/envs/pipeline/lib/python3.11/site-packages/torch/utils/data/dataloader.py", line 633, in __next__
    data = self._next_data()
           ^^^^^^^^^^^^^^^^^
  File "/nas-ctm01/homes/mipaiva/.conda/envs/pipeline/lib/python3.11/site-packages/torch/utils/data/dataloader.py", line 1345, in _next_data
    return self._process_data(data)
           ^^^^^^^^^^^^^^^^^^^^^^^^
  File "/nas-ctm01/homes/mipaiva/.conda/envs/pipeline/lib/python3.11/site-packages/torch/utils/data/dataloader.py", line 1371, in _process_data
    data.reraise()
  File "/nas-ctm01/homes/mipaiva/.conda/envs/pipeline/lib/python3.11/site-packages/torch/_utils.py", line 644, in reraise
    raise exception
ValueError: Caught ValueError in DataLoader worker process 1.
Original Traceback (most recent call last):
  File "/nas-ctm01/homes/mipaiva/.conda/envs/pipeline/lib/python3.11/site-packages/torch/utils/data/_utils/worker.py", line 308, in _worker_loop
    data = fetcher.fetch(index)
           ^^^^^^^^^^^^^^^^^^^^
  File "/nas-ctm01/homes/mipaiva/.conda/envs/pipeline/lib/python3.11/site-packages/torch/utils/data/_utils/fetch.py", line 51, in fetch
    data = [self.dataset[idx] for idx in possibly_batched_index]
           ^^^^^^^^^^^^^^^^^^^^^^^^^^^^^^^^^^^^^^^^^^^^^^^^^^^^^
  File "/nas-ctm01/homes/mipaiva/.conda/envs/pipeline/lib/python3.11/site-packages/torch/utils/data/_utils/fetch.py", line 51, in <listcomp>
    data = [self.dataset[idx] for idx in possibly_batched_index]
            ~~~~~~~~~~~~^^^^^
  File "/nas-ctm01/homes/mipaiva/pipeline_template_pl/src/modules/data/dataloader/preprocessed_dataloaders/nlst_preprocessed_dataloader.py", line 224, in __getitem__
    data = self._get_data(data_index)
           ^^^^^^^^^^^^^^^^^^^^^^^^^^
  File "/nas-ctm01/homes/mipaiva/pipeline_template_pl/src/modules/data/dataloader/preprocessed_dataloaders/nlst_preprocessed_dataloader.py", line 241, in _get_data
    raise ValueError(f"[ERROR] Image is None at index {data_index}. File info: {self.lung_metadataframe.loc[self.lung_metadataframe['path'] == self.file_names[data_index]]}")
ValueError: [ERROR] Image is None at index 259. File info:        pid  study_yr  ... label sct_slice_num
49  106046         0  ...     0           166

[1 rows x 6 columns]


Set the environment variable HYDRA_FULL_ERROR=1 for a complete stack trace.
srun: error: 01.ctm-deep-08: task 0: Exited with exit code 1
/nas-ctm01/homes/mipaiva/.conda/envs/pipeline/lib/python3.11/site-packages/torchvision/models/_utils.py:208: UserWarning: The parameter 'pretrained' is deprecated since 0.13 and may be removed in the future, please use 'weights' instead.
  warnings.warn(
/nas-ctm01/homes/mipaiva/.conda/envs/pipeline/lib/python3.11/site-packages/torchvision/models/_utils.py:223: UserWarning: Arguments other than a weight enum or `None` for 'weights' are deprecated since 0.13 and may be removed in the future. The current behavior is equivalent to passing `weights=None`.
  warnings.warn(msg)

**************************************************  Experiment 45 | Version 1 **************************************************
Label column '5y' found in metadata. Available columns: ['pid', 'study_yr', 'path', 'sct_slice_num_og', 'stage', '1y', '2y', '5y', '10y', 'fup_days', 'sct_nod_err']

Running model pipeline for data fold 1...
Label column '5y' found in metadata. Available columns: ['pid', 'study_yr', 'path', 'sct_slice_num_og', 'stage', '1y', '2y', '5y', '10y', 'fup_days', 'sct_nod_err']
Error executing job with overrides: []
Traceback (most recent call last):
  File "/nas-ctm01/homes/mipaiva/pipeline_template_pl/slurm_files/shell_script_files/../../src/scripts/run_experiment_pipeline.py", line 53, in run_hyperparameter_grid_based_execution_pipeline
    run_experiment_pipeline(config)
  File "/nas-ctm01/homes/mipaiva/pipeline_template_pl/slurm_files/shell_script_files/../../src/scripts/run_experiment_pipeline.py", line 139, in run_experiment_pipeline
    model_pipeline.train_model()
  File "/nas-ctm01/homes/mipaiva/pipeline_template_pl/src/modules/model/model_pipeline.py", line 67, in train_model
    self.pytorch_lightning_trainer.fit(
  File "/nas-ctm01/homes/mipaiva/.conda/envs/pipeline/lib/python3.11/site-packages/pytorch_lightning/trainer/trainer.py", line 532, in fit
    call._call_and_handle_interrupt(
  File "/nas-ctm01/homes/mipaiva/.conda/envs/pipeline/lib/python3.11/site-packages/pytorch_lightning/trainer/call.py", line 43, in _call_and_handle_interrupt
    return trainer_fn(*args, **kwargs)
           ^^^^^^^^^^^^^^^^^^^^^^^^^^^
  File "/nas-ctm01/homes/mipaiva/.conda/envs/pipeline/lib/python3.11/site-packages/pytorch_lightning/trainer/trainer.py", line 571, in _fit_impl
    self._run(model, ckpt_path=ckpt_path)
  File "/nas-ctm01/homes/mipaiva/.conda/envs/pipeline/lib/python3.11/site-packages/pytorch_lightning/trainer/trainer.py", line 980, in _run
    results = self._run_stage()
              ^^^^^^^^^^^^^^^^^
  File "/nas-ctm01/homes/mipaiva/.conda/envs/pipeline/lib/python3.11/site-packages/pytorch_lightning/trainer/trainer.py", line 1023, in _run_stage
    self.fit_loop.run()
  File "/nas-ctm01/homes/mipaiva/.conda/envs/pipeline/lib/python3.11/site-packages/pytorch_lightning/loops/fit_loop.py", line 202, in run
    self.advance()
  File "/nas-ctm01/homes/mipaiva/.conda/envs/pipeline/lib/python3.11/site-packages/pytorch_lightning/loops/fit_loop.py", line 355, in advance
    self.epoch_loop.run(self._data_fetcher)
  File "/nas-ctm01/homes/mipaiva/.conda/envs/pipeline/lib/python3.11/site-packages/pytorch_lightning/loops/training_epoch_loop.py", line 133, in run
    self.advance(data_fetcher)
  File "/nas-ctm01/homes/mipaiva/.conda/envs/pipeline/lib/python3.11/site-packages/pytorch_lightning/loops/training_epoch_loop.py", line 190, in advance
    batch = next(data_fetcher)
            ^^^^^^^^^^^^^^^^^^
  File "/nas-ctm01/homes/mipaiva/.conda/envs/pipeline/lib/python3.11/site-packages/pytorch_lightning/loops/fetchers.py", line 126, in __next__
    batch = super().__next__()
            ^^^^^^^^^^^^^^^^^^
  File "/nas-ctm01/homes/mipaiva/.conda/envs/pipeline/lib/python3.11/site-packages/pytorch_lightning/loops/fetchers.py", line 58, in __next__
    batch = next(self.iterator)
            ^^^^^^^^^^^^^^^^^^^
  File "/nas-ctm01/homes/mipaiva/.conda/envs/pipeline/lib/python3.11/site-packages/pytorch_lightning/utilities/combined_loader.py", line 285, in __next__
    out = next(self._iterator)
          ^^^^^^^^^^^^^^^^^^^^
  File "/nas-ctm01/homes/mipaiva/.conda/envs/pipeline/lib/python3.11/site-packages/pytorch_lightning/utilities/combined_loader.py", line 65, in __next__
    out[i] = next(self.iterators[i])
             ^^^^^^^^^^^^^^^^^^^^^^^
  File "/nas-ctm01/homes/mipaiva/.conda/envs/pipeline/lib/python3.11/site-packages/torch/utils/data/dataloader.py", line 633, in __next__
    data = self._next_data()
           ^^^^^^^^^^^^^^^^^
  File "/nas-ctm01/homes/mipaiva/.conda/envs/pipeline/lib/python3.11/site-packages/torch/utils/data/dataloader.py", line 1325, in _next_data
    return self._process_data(data)
           ^^^^^^^^^^^^^^^^^^^^^^^^
  File "/nas-ctm01/homes/mipaiva/.conda/envs/pipeline/lib/python3.11/site-packages/torch/utils/data/dataloader.py", line 1371, in _process_data
    data.reraise()
  File "/nas-ctm01/homes/mipaiva/.conda/envs/pipeline/lib/python3.11/site-packages/torch/_utils.py", line 644, in reraise
    raise exception
ValueError: Caught ValueError in DataLoader worker process 1.
Original Traceback (most recent call last):
  File "/nas-ctm01/homes/mipaiva/.conda/envs/pipeline/lib/python3.11/site-packages/torch/utils/data/_utils/worker.py", line 308, in _worker_loop
    data = fetcher.fetch(index)
           ^^^^^^^^^^^^^^^^^^^^
  File "/nas-ctm01/homes/mipaiva/.conda/envs/pipeline/lib/python3.11/site-packages/torch/utils/data/_utils/fetch.py", line 51, in fetch
    data = [self.dataset[idx] for idx in possibly_batched_index]
           ^^^^^^^^^^^^^^^^^^^^^^^^^^^^^^^^^^^^^^^^^^^^^^^^^^^^^
  File "/nas-ctm01/homes/mipaiva/.conda/envs/pipeline/lib/python3.11/site-packages/torch/utils/data/_utils/fetch.py", line 51, in <listcomp>
    data = [self.dataset[idx] for idx in possibly_batched_index]
            ~~~~~~~~~~~~^^^^^
  File "/nas-ctm01/homes/mipaiva/pipeline_template_pl/src/modules/data/dataloader/preprocessed_dataloaders/nlst_preprocessed_dataloader.py", line 224, in __getitem__
    data = self._get_data(data_index)
           ^^^^^^^^^^^^^^^^^^^^^^^^^^
  File "/nas-ctm01/homes/mipaiva/pipeline_template_pl/src/modules/data/dataloader/preprocessed_dataloaders/nlst_preprocessed_dataloader.py", line 241, in _get_data
    raise ValueError(f"[ERROR] Image is None at index {data_index}. File info: {self.lung_metadataframe.loc[self.lung_metadataframe['path'] == self.file_names[data_index]]}")
ValueError: [ERROR] Image is None at index 259. File info:        pid  study_yr  ... label sct_slice_num
49  106046         0  ...     0           166

[1 rows x 6 columns]


Set the environment variable HYDRA_FULL_ERROR=1 for a complete stack trace.
srun: error: 01.ctm-deep-08: task 0: Exited with exit code 1
Finish time: 2025-05-14 22:02:54
