Initialization time: 2025-05-16 23:55:23
wandb: Currently logged in as: maria-i-paiva (maria-i-paiva-inesc-tec) to https://api.wandb.ai. Use `wandb login --relogin` to force relogin
wandb: WARNING Using a boolean value for 'reinit' is deprecated. Use 'return_previous' or 'finish_previous' instead.
wandb: Tracking run with wandb version 0.19.11
wandb: Run data is saved locally in /nas-ctm01/homes/mipaiva/pipeline_template_pl/experiment_results/experiment_75/version_1/wandb/run-20250516_235530-h6yq28c8
wandb: Run `wandb offline` to turn off syncing.
wandb: Syncing run resnet50_25d_75_1_fold1
wandb: ⭐️ View project at https://wandb.ai/maria-i-paiva-inesc-tec/comparative_study_25
wandb: 🚀 View run at https://wandb.ai/maria-i-paiva-inesc-tec/comparative_study_25/runs/h6yq28c8

**************************************************  Experiment 75 | Version 1 **************************************************
Label column '5y' found in metadata. Available columns: ['pid', 'study_yr', 'path', 'sct_slice_num_og', 'stage', '1y', '2y', '5y', '10y', 'fup_days', 'sct_nod_err']

Running model pipeline for data fold 1...
Label column '5y' found in metadata. Available columns: ['pid', 'study_yr', 'path', 'sct_slice_num_og', 'stage', '1y', '2y', '5y', '10y', 'fup_days', 'sct_nod_err']
wandb:                                                                                
wandb: 
wandb: Run history:
wandb:  test_accuracy ▁██
wandb:     test_auroc ▁██
wandb: test_precision █▁▁
wandb:    test_recall █▁▁
wandb:    train_auroc ▇▇▇▇▅▇▇▇▇▇▇▇▇▇▇█▇▇▇▁▇▇▇▇▇▇▇▇▇▇▇
wandb:     train_loss ▁▁█▁▁▁▁▁▁▁▁▁▁▁▁▁▁▁▁▂▁▁▁▁▁▁▁▁▁▂▁
wandb:   val_accuracy ▁████▆██████████████▃███████████
wandb:      val_auroc ▇▇▇▇▇▅▇▇▇▇▇▇▇▇▇▇█▇▇▇▁▇▇▇▇▇▇▇▇▇▇▇
wandb:       val_loss █▁▁▁▁▁▁▁▁▁▁▁▁▁▁▁▁▁▁▁▁▁▁▁▁▁▁▁▁▁▁▁
wandb:  val_precision ▆▁▁▁▁▅▁▁▁▁▁▁▁▁▁▁█▁▁▁▅▁▁▁▁▁▁▁▁▁▁▁
wandb:     val_recall █▁▁▁▁▂▁▁▁▁▁▁▁▁▁▁▂▁▁▁▄▁▁▁▁▁▁▁▁▁▁▁
wandb: 
wandb: Run summary:
wandb:  test_accuracy 0.74684
wandb:     test_auroc 0.5
wandb: test_precision 0
wandb:    test_recall 0
wandb:    train_auroc 0.5
wandb:     train_loss 0.37697
wandb:   val_accuracy 0.75
wandb:      val_auroc 0.5
wandb:       val_loss 0.37697
wandb:  val_precision 0
wandb:     val_recall 0
wandb: 
wandb: 🚀 View run resnet50_25d_75_1_fold1 at: https://wandb.ai/maria-i-paiva-inesc-tec/comparative_study_25/runs/h6yq28c8
wandb: ⭐️ View project at: https://wandb.ai/maria-i-paiva-inesc-tec/comparative_study_25
wandb: Synced 5 W&B file(s), 0 media file(s), 0 artifact file(s) and 0 other file(s)
wandb: Find logs at: /nas-ctm01/homes/mipaiva/pipeline_template_pl/experiment_results/experiment_75/version_1/wandb/run-20250516_235530-h6yq28c8/logs
wandb: Tracking run with wandb version 0.19.11
wandb: Run data is saved locally in /nas-ctm01/homes/mipaiva/pipeline_template_pl/experiment_results/experiment_75/version_2/wandb/run-20250517_000502-t2liae4s
wandb: Run `wandb offline` to turn off syncing.
wandb: Syncing run resnet50_25d_75_2_fold1
wandb: ⭐️ View project at https://wandb.ai/maria-i-paiva-inesc-tec/comparative_study_25
wandb: 🚀 View run at https://wandb.ai/maria-i-paiva-inesc-tec/comparative_study_25/runs/t2liae4s
...model pipeline for data fold 1 has run!
Saving execution datetimes to /nas-ctm01/homes/mipaiva/pipeline_template_pl/experiment_results/experiment_75/version_1/execution_datetimes.json

**************************************************  Experiment 75 | Version 2 **************************************************
Label column '5y' found in metadata. Available columns: ['pid', 'study_yr', 'path', 'sct_slice_num_og', 'stage', '1y', '2y', '5y', '10y', 'fup_days', 'sct_nod_err']

Running model pipeline for data fold 1...
Label column '5y' found in metadata. Available columns: ['pid', 'study_yr', 'path', 'sct_slice_num_og', 'stage', '1y', '2y', '5y', '10y', 'fup_days', 'sct_nod_err']
srun: got SIGCONT
slurmstepd-01.ctm-deep-08: error: *** STEP 3855.0 ON 01.ctm-deep-08 CANCELLED AT 2025-05-17T00:10:00 ***
slurmstepd-01.ctm-deep-08: error: *** JOB 3855 ON 01.ctm-deep-08 CANCELLED AT 2025-05-17T00:10:00 ***
srun: forcing job termination
srun: Job step aborted: Waiting up to 32 seconds for job step to finish.
Error executing job with overrides: []
Traceback (most recent call last):
  File "/nas-ctm01/homes/mipaiva/.conda/envs/pipeline/lib/python3.11/site-packages/torch/utils/data/dataloader.py", line 1132, in _try_get_data
    data = self._data_queue.get(timeout=timeout)
           ^^^^^^^^^^^^^^^^^^^^^^^^^^^^^^^^^^^^^
  File "/nas-ctm01/homes/mipaiva/.conda/envs/pipeline/lib/python3.11/multiprocessing/queues.py", line 114, in get
    raise Empty
_queue.Empty

The above exception was the direct cause of the following exception:

Traceback (most recent call last):
  File "/nas-ctm01/homes/mipaiva/pipeline_template_pl/slurm_files/shell_script_files/../../src/scripts/run_experiment_pipeline.py", line 54, in run_hyperparameter_grid_based_execution_pipeline
    run_experiment_pipeline(config)
  File "/nas-ctm01/homes/mipaiva/pipeline_template_pl/slurm_files/shell_script_files/../../src/scripts/run_experiment_pipeline.py", line 155, in run_experiment_pipeline
    model_pipeline.train_model()
  File "/nas-ctm01/homes/mipaiva/pipeline_template_pl/src/modules/model/model_pipeline.py", line 67, in train_model
    self.pytorch_lightning_trainer.fit(
  File "/nas-ctm01/homes/mipaiva/.conda/envs/pipeline/lib/python3.11/site-packages/pytorch_lightning/trainer/trainer.py", line 532, in fit
    call._call_and_handle_interrupt(
  File "/nas-ctm01/homes/mipaiva/.conda/envs/pipeline/lib/python3.11/site-packages/pytorch_lightning/trainer/call.py", line 43, in _call_and_handle_interrupt
    return trainer_fn(*args, **kwargs)
           ^^^^^^^^^^^^^^^^^^^^^^^^^^^
  File "/nas-ctm01/homes/mipaiva/.conda/envs/pipeline/lib/python3.11/site-packages/pytorch_lightning/trainer/trainer.py", line 571, in _fit_impl
    self._run(model, ckpt_path=ckpt_path)
  File "/nas-ctm01/homes/mipaiva/.conda/envs/pipeline/lib/python3.11/site-packages/pytorch_lightning/trainer/trainer.py", line 980, in _run
    results = self._run_stage()
              ^^^^^^^^^^^^^^^^^
  File "/nas-ctm01/homes/mipaiva/.conda/envs/pipeline/lib/python3.11/site-packages/pytorch_lightning/trainer/trainer.py", line 1023, in _run_stage
    self.fit_loop.run()
  File "/nas-ctm01/homes/mipaiva/.conda/envs/pipeline/lib/python3.11/site-packages/pytorch_lightning/loops/fit_loop.py", line 202, in run
    self.advance()
  File "/nas-ctm01/homes/mipaiva/.conda/envs/pipeline/lib/python3.11/site-packages/pytorch_lightning/loops/fit_loop.py", line 355, in advance
    self.epoch_loop.run(self._data_fetcher)
  File "/nas-ctm01/homes/mipaiva/.conda/envs/pipeline/lib/python3.11/site-packages/pytorch_lightning/loops/training_epoch_loop.py", line 134, in run
    self.on_advance_end()
  File "/nas-ctm01/homes/mipaiva/.conda/envs/pipeline/lib/python3.11/site-packages/pytorch_lightning/loops/training_epoch_loop.py", line 249, in on_advance_end
    self.val_loop.run()
  File "/nas-ctm01/homes/mipaiva/.conda/envs/pipeline/lib/python3.11/site-packages/pytorch_lightning/loops/utilities.py", line 181, in _decorator
    return loop_run(self, *args, **kwargs)
           ^^^^^^^^^^^^^^^^^^^^^^^^^^^^^^^
  File "/nas-ctm01/homes/mipaiva/.conda/envs/pipeline/lib/python3.11/site-packages/pytorch_lightning/loops/evaluation_loop.py", line 108, in run
    batch, batch_idx, dataloader_idx = next(data_fetcher)
                                       ^^^^^^^^^^^^^^^^^^
  File "/nas-ctm01/homes/mipaiva/.conda/envs/pipeline/lib/python3.11/site-packages/pytorch_lightning/loops/fetchers.py", line 126, in __next__
    batch = super().__next__()
            ^^^^^^^^^^^^^^^^^^
  File "/nas-ctm01/homes/mipaiva/.conda/envs/pipeline/lib/python3.11/site-packages/pytorch_lightning/loops/fetchers.py", line 58, in __next__
    batch = next(self.iterator)
            ^^^^^^^^^^^^^^^^^^^
  File "/nas-ctm01/homes/mipaiva/.conda/envs/pipeline/lib/python3.11/site-packages/pytorch_lightning/utilities/combined_loader.py", line 285, in __next__
    out = next(self._iterator)
          ^^^^^^^^^^^^^^^^^^^^
  File "/nas-ctm01/homes/mipaiva/.conda/envs/pipeline/lib/python3.11/site-packages/pytorch_lightning/utilities/combined_loader.py", line 123, in __next__
    out = next(self.iterators[0])
          ^^^^^^^^^^^^^^^^^^^^^^^
  File "/nas-ctm01/homes/mipaiva/.conda/envs/pipeline/lib/python3.11/site-packages/torch/utils/data/dataloader.py", line 633, in __next__
    data = self._next_data()
           ^^^^^^^^^^^^^^^^^
  File "/nas-ctm01/homes/mipaiva/.conda/envs/pipeline/lib/python3.11/site-packages/torch/utils/data/dataloader.py", line 1328, in _next_data
    idx, data = self._get_data()
                ^^^^^^^^^^^^^^^^
  File "/nas-ctm01/homes/mipaiva/.conda/envs/pipeline/lib/python3.11/site-packages/torch/utils/data/dataloader.py", line 1294, in _get_data
    success, data = self._try_get_data()
                    ^^^^^^^^^^^^^^^^^^^^
  File "/nas-ctm01/homes/mipaiva/.conda/envs/pipeline/lib/python3.11/site-packages/torch/utils/data/dataloader.py", line 1145, in _try_get_data
    raise RuntimeError('DataLoader worker (pid(s) {}) exited unexpectedly'.format(pids_str)) from e
RuntimeError: DataLoader worker (pid(s) 492451, 492465, 492479, 492493, 492507, 492521, 492535, 492549, 492563, 492577, 492591, 492605, 492619, 492633) exited unexpectedly

Set the environment variable HYDRA_FULL_ERROR=1 for a complete stack trace.
Exception ignored in atexit callback: <function _start_and_connect_service.<locals>.teardown_atexit at 0x7bac25004c20>
Traceback (most recent call last):
  File "/nas-ctm01/homes/mipaiva/.conda/envs/pipeline/lib/python3.11/site-packages/wandb/sdk/lib/service_connection.py", line 94, in teardown_atexit
    conn.teardown(hooks.exit_code)
  File "/nas-ctm01/homes/mipaiva/.conda/envs/pipeline/lib/python3.11/site-packages/wandb/sdk/lib/service_connection.py", line 228, in teardown
    self._client.send_server_request(
  File "/nas-ctm01/homes/mipaiva/.conda/envs/pipeline/lib/python3.11/site-packages/wandb/sdk/lib/sock_client.py", line 154, in send_server_request
    self._send_message(msg)
  File "/nas-ctm01/homes/mipaiva/.conda/envs/pipeline/lib/python3.11/site-packages/wandb/sdk/lib/sock_client.py", line 151, in _send_message
    self._sendall_with_error_handle(header + data)
  File "/nas-ctm01/homes/mipaiva/.conda/envs/pipeline/lib/python3.11/site-packages/wandb/sdk/lib/sock_client.py", line 130, in _sendall_with_error_handle
    sent = self._sock.send(data)
           ^^^^^^^^^^^^^^^^^^^^^
BrokenPipeError: [Errno 32] Broken pipe
srun: error: 01.ctm-deep-08: task 0: Exited with exit code 1
