Initialization time: 2025-05-12 03:45:56
/nas-ctm01/homes/mipaiva/pipeline_template_pl/slurm_files/shell_script_files/../../src/scripts/run_experiment_pipeline.py:29: UserWarning: 
The version_base parameter is not specified.
Please specify a compatability version level, or None.
Will assume defaults for version 1.1
  @hydra.main(config_path=config_path, config_name="main")
/nas-ctm01/homes/mipaiva/.conda/envs/pipeline/lib/python3.11/site-packages/hydra/_internal/hydra.py:119: UserWarning: Future Hydra versions will no longer change working directory at job runtime by default.
See https://hydra.cc/docs/1.2/upgrades/1.1_to_1.2/changes_to_job_working_dir/ for more information.
  ret = run_job(
Running experiment pipeline with config: ../../config_files

**************************************************  Experiment 38 | Version 1 **************************************************
Label column '5y' found in metadata. Available columns: ['pid', 'study_yr', 'path', 'sct_slice_num_og', 'stage', '1y', '2y', '5y', '10y', 'fup_days', 'sct_nod_err']

Running model pipeline for data fold 1...
Label column '5y' found in metadata. Available columns: ['pid', 'study_yr', 'path', 'sct_slice_num_og', 'stage', '1y', '2y', '5y', '10y', 'fup_days', 'sct_nod_err']
...model pipeline for data fold 1 has run!

Running model pipeline for data fold 2...
Label column '5y' found in metadata. Available columns: ['pid', 'study_yr', 'path', 'sct_slice_num_og', 'stage', '1y', '2y', '5y', '10y', 'fup_days', 'sct_nod_err']
...model pipeline for data fold 2 has run!

Running model pipeline for data fold 3...
Label column '5y' found in metadata. Available columns: ['pid', 'study_yr', 'path', 'sct_slice_num_og', 'stage', '1y', '2y', '5y', '10y', 'fup_days', 'sct_nod_err']
...model pipeline for data fold 3 has run!

Running model pipeline for data fold 4...
Label column '5y' found in metadata. Available columns: ['pid', 'study_yr', 'path', 'sct_slice_num_og', 'stage', '1y', '2y', '5y', '10y', 'fup_days', 'sct_nod_err']
...model pipeline for data fold 4 has run!

Running model pipeline for data fold 5...
Label column '5y' found in metadata. Available columns: ['pid', 'study_yr', 'path', 'sct_slice_num_og', 'stage', '1y', '2y', '5y', '10y', 'fup_days', 'sct_nod_err']
srun: got SIGCONT
slurmstepd-04.ctm-deep-06: error: *** STEP 1996.0 ON 04.ctm-deep-06 CANCELLED AT 2025-05-12T17:51:23 ***
slurmstepd-04.ctm-deep-06: error: *** JOB 1996 ON 04.ctm-deep-06 CANCELLED AT 2025-05-12T17:51:23 ***
srun: forcing job termination
srun: Job step aborted: Waiting up to 32 seconds for job step to finish.
Error executing job with overrides: []
Traceback (most recent call last):
  File "/nas-ctm01/homes/mipaiva/.conda/envs/pipeline/lib/python3.11/site-packages/torch/utils/data/dataloader.py", line 1132, in _try_get_data
    data = self._data_queue.get(timeout=timeout)
           ^^^^^^^^^^^^^^^^^^^^^^^^^^^^^^^^^^^^^
  File "/nas-ctm01/homes/mipaiva/.conda/envs/pipeline/lib/python3.11/multiprocessing/queues.py", line 114, in get
    raise Empty
_queue.Empty

The above exception was the direct cause of the following exception:

Traceback (most recent call last):
  File "/nas-ctm01/homes/mipaiva/pipeline_template_pl/slurm_files/shell_script_files/../../src/scripts/run_experiment_pipeline.py", line 32, in _main
    run_hyperparameter_grid_based_execution_pipeline(config)
  File "/nas-ctm01/homes/mipaiva/pipeline_template_pl/slurm_files/shell_script_files/../../src/scripts/run_experiment_pipeline.py", line 60, in run_hyperparameter_grid_based_execution_pipeline
    run_experiment_pipeline(config)
  File "/nas-ctm01/homes/mipaiva/pipeline_template_pl/slurm_files/shell_script_files/../../src/scripts/run_experiment_pipeline.py", line 141, in run_experiment_pipeline
    model_pipeline.train_model()
  File "/nas-ctm01/homes/mipaiva/pipeline_template_pl/src/modules/model/model_pipeline.py", line 67, in train_model
    self.pytorch_lightning_trainer.fit(
  File "/nas-ctm01/homes/mipaiva/.conda/envs/pipeline/lib/python3.11/site-packages/pytorch_lightning/trainer/trainer.py", line 532, in fit
    call._call_and_handle_interrupt(
  File "/nas-ctm01/homes/mipaiva/.conda/envs/pipeline/lib/python3.11/site-packages/pytorch_lightning/trainer/call.py", line 43, in _call_and_handle_interrupt
    return trainer_fn(*args, **kwargs)
           ^^^^^^^^^^^^^^^^^^^^^^^^^^^
  File "/nas-ctm01/homes/mipaiva/.conda/envs/pipeline/lib/python3.11/site-packages/pytorch_lightning/trainer/trainer.py", line 571, in _fit_impl
    self._run(model, ckpt_path=ckpt_path)
  File "/nas-ctm01/homes/mipaiva/.conda/envs/pipeline/lib/python3.11/site-packages/pytorch_lightning/trainer/trainer.py", line 980, in _run
    results = self._run_stage()
              ^^^^^^^^^^^^^^^^^
  File "/nas-ctm01/homes/mipaiva/.conda/envs/pipeline/lib/python3.11/site-packages/pytorch_lightning/trainer/trainer.py", line 1023, in _run_stage
    self.fit_loop.run()
  File "/nas-ctm01/homes/mipaiva/.conda/envs/pipeline/lib/python3.11/site-packages/pytorch_lightning/loops/fit_loop.py", line 202, in run
    self.advance()
  File "/nas-ctm01/homes/mipaiva/.conda/envs/pipeline/lib/python3.11/site-packages/pytorch_lightning/loops/fit_loop.py", line 355, in advance
    self.epoch_loop.run(self._data_fetcher)
  File "/nas-ctm01/homes/mipaiva/.conda/envs/pipeline/lib/python3.11/site-packages/pytorch_lightning/loops/training_epoch_loop.py", line 133, in run
    self.advance(data_fetcher)
  File "/nas-ctm01/homes/mipaiva/.conda/envs/pipeline/lib/python3.11/site-packages/pytorch_lightning/loops/training_epoch_loop.py", line 190, in advance
    batch = next(data_fetcher)
            ^^^^^^^^^^^^^^^^^^
  File "/nas-ctm01/homes/mipaiva/.conda/envs/pipeline/lib/python3.11/site-packages/pytorch_lightning/loops/fetchers.py", line 126, in __next__
    batch = super().__next__()
            ^^^^^^^^^^^^^^^^^^
  File "/nas-ctm01/homes/mipaiva/.conda/envs/pipeline/lib/python3.11/site-packages/pytorch_lightning/loops/fetchers.py", line 58, in __next__
    batch = next(self.iterator)
            ^^^^^^^^^^^^^^^^^^^
  File "/nas-ctm01/homes/mipaiva/.conda/envs/pipeline/lib/python3.11/site-packages/pytorch_lightning/utilities/combined_loader.py", line 285, in __next__
    out = next(self._iterator)
          ^^^^^^^^^^^^^^^^^^^^
  File "/nas-ctm01/homes/mipaiva/.conda/envs/pipeline/lib/python3.11/site-packages/pytorch_lightning/utilities/combined_loader.py", line 65, in __next__
    out[i] = next(self.iterators[i])
             ^^^^^^^^^^^^^^^^^^^^^^^
  File "/nas-ctm01/homes/mipaiva/.conda/envs/pipeline/lib/python3.11/site-packages/torch/utils/data/dataloader.py", line 633, in __next__
    data = self._next_data()
           ^^^^^^^^^^^^^^^^^
  File "/nas-ctm01/homes/mipaiva/.conda/envs/pipeline/lib/python3.11/site-packages/torch/utils/data/dataloader.py", line 1328, in _next_data
    idx, data = self._get_data()
                ^^^^^^^^^^^^^^^^
  File "/nas-ctm01/homes/mipaiva/.conda/envs/pipeline/lib/python3.11/site-packages/torch/utils/data/dataloader.py", line 1294, in _get_data
    success, data = self._try_get_data()
                    ^^^^^^^^^^^^^^^^^^^^
  File "/nas-ctm01/homes/mipaiva/.conda/envs/pipeline/lib/python3.11/site-packages/torch/utils/data/dataloader.py", line 1145, in _try_get_data
    raise RuntimeError('DataLoader worker (pid(s) {}) exited unexpectedly'.format(pids_str)) from e
RuntimeError: DataLoader worker (pid(s) 610477, 610533, 610589, 610645) exited unexpectedly

Set the environment variable HYDRA_FULL_ERROR=1 for a complete stack trace.
srun: error: 04.ctm-deep-06: task 0: Exited with exit code 1
